# [Bug] 在 axios 响应拦截器里抛出错误后优先被 umi 捕获而导致无法被 axios 的捕获

```
const service = axios.create({
timeout: 8000,
baseURL: '...',
});

service.interceptors.response.use(
(response) => {
  if (response.data?.code !== 0) {
    const error: any = new Error('服务器报错了');
    error.name = 'RequestError';
    error.info = response.data;

    return Promise.reject(error);
  }

  console.log(response.data);

  return response.data;
},
(error) => {
  console.dir(error);

  if (error.code === 'ERR_CANCELED') {
    return new Promise(() => {});
  }

  if (error.name === 'RequestError') {
    if (error.info.code === -2) {
      // ....
    }
  }

  return Promise.reject(error);
},
);

...

getList_()

...

```

![image](https://github.com/umijs/umi/assets/130121019/56b98b78-2496-4aa6-a631-d5ddb312b391)

## fz6m

这里已经正常响应了，进入了第一部分的逻辑，但是你抛出了 `服务器报错了` 这个 error ，控制台也如期打印了这个错误，没有问题。
